Workbook

Sheet Overview
A1: Property superapp: brokerage launch and pilot roadmap
A2: Phased plan to open a RERA-licensed brokerage, run a pilot in about 9-13 weeks, and raise funds. Change the yellow cell and every date recalculates.
B4: Inputs
B5: Project start date (Monday) | C5: 46307 | D5: Working week assumed Monday to Friday. Weekend is Saturday and Sunday.
B6: Pilot go-live date | C6: =INDEX(Roadmap!$L$5:$L$59,MATCH("2.14",Roadmap!$A$5:$A$59,0)) -> 46363 | D6: From milestone M2 in the Roadmap.
B7: Weeks from start to pilot go-live | C7: =INDEX(Roadmap!$I$5:$I$59,MATCH("2.14",Roadmap!$A$5:$A$59,0)) -> 9
B9: Phase summary
B10: Phase | C10: Goal | D10: Start wk | E10: End wk | F10: Tasks | G10: Done | H10: % done | I10: Cost AED
B11: P0 Validate | C11: Prove the problem is real and the model is legal | D11: =_xlfn.MINIFS(Roadmap!$I$5:$I$59,Roadmap!$B$5:$B$59,B11) -> 1 | E11: =_xlfn.MAXIFS(Roadmap!$K$5:$K$59,Roadmap!$B$5:$B$59,B11) -> 6 | F11: =COUNTIF(Roadmap!$B$5:$B$59,B11) -> 13 | G11: =COUNTIFS(Roadmap!$B$5:$B$59,B11,Roadmap!$Q$5:$Q$59,"Done") -> 0 | H11: =IFERROR(G11/F11,0) -> 0 | I11: =SUMIFS(Roadmap!$P$5:$P$59,Roadmap!$B$5:$B$59,B11) -> 25500
B12: P1 Set up | C12: Get licensed and operating | D12: =_xlfn.MINIFS(Roadmap!$I$5:$I$59,Roadmap!$B$5:$B$59,B12) -> 2 | E12: =_xlfn.MAXIFS(Roadmap!$K$5:$K$59,Roadmap!$B$5:$B$59,B12) -> 8 | F12: =COUNTIF(Roadmap!$B$5:$B$59,B12) -> 17 | G12: =COUNTIFS(Roadmap!$B$5:$B$59,B12,Roadmap!$Q$5:$Q$59,"Done") -> 0 | H12: =IFERROR(G12/F12,0) -> 0 | I12: =SUMIFS(Roadmap!$P$5:$P$59,Roadmap!$B$5:$B$59,B12) -> 93000
B13: P2 Pilot | C13: Build, launch and run a small real pilot | D13: =_xlfn.MINIFS(Roadmap!$I$5:$I$59,Roadmap!$B$5:$B$59,B13) -> 4 | E13: =_xlfn.MAXIFS(Roadmap!$K$5:$K$59,Roadmap!$B$5:$B$59,B13) -> 13 | F13: =COUNTIF(Roadmap!$B$5:$B$59,B13) -> 17 | G13: =COUNTIFS(Roadmap!$B$5:$B$59,B13,Roadmap!$Q$5:$Q$59,"Done") -> 0 | H13: =IFERROR(G13/F13,0) -> 0 | I13: =SUMIFS(Roadmap!$P$5:$P$59,Roadmap!$B$5:$B$59,B13) -> 49000
B14: P3 Raise | C14: Turn evidence into an investor round | D14: =_xlfn.MINIFS(Roadmap!$I$5:$I$59,Roadmap!$B$5:$B$59,B14) -> 7 | E14: =_xlfn.MAXIFS(Roadmap!$K$5:$K$59,Roadmap!$B$5:$B$59,B14) -> 20 | F14: =COUNTIF(Roadmap!$B$5:$B$59,B14) -> 8 | G14: =COUNTIFS(Roadmap!$B$5:$B$59,B14,Roadmap!$Q$5:$Q$59,"Done") -> 0 | H14: =IFERROR(G14/F14,0) -> 0 | I14: =SUMIFS(Roadmap!$P$5:$P$59,Roadmap!$B$5:$B$59,B14) -> 8000
B15: Total | F15: =SUM(F11:F14) -> 55 | G15: =SUM(G11:G14) -> 0 | H15: =IFERROR(G15/F15,0) -> 0 | I15: =SUM(I11:I14) -> 175500
B17: Gate status
B18: Gate | C18: Stage | D18: Criteria | E18: Met | F18: Not met | G18: Pending
B19: G0 | C19: Week 6: problem and plan validated | D19: =COUNTIF(Gates!$A$5:$A$26,B19) -> 6 | E19: =COUNTIFS(Gates!$A$5:$A$26,$B19,Gates!$G$5:$G$26,"Met") -> 0 | F19: =COUNTIFS(Gates!$A$5:$A$26,$B19,Gates!$G$5:$G$26,"Not met") -> 0 | G19: =COUNTIFS(Gates!$A$5:$A$26,$B19,Gates!$G$5:$G$26,"Pending") -> 6
B20: G1 | C20: Week 8: licensed and pilot-ready | D20: =COUNTIF(Gates!$A$5:$A$26,B20) -> 7 | E20: =COUNTIFS(Gates!$A$5:$A$26,$B20,Gates!$G$5:$G$26,"Met") -> 0 | F20: =COUNTIFS(Gates!$A$5:$A$26,$B20,Gates!$G$5:$G$26,"Not met") -> 0 | G20: =COUNTIFS(Gates!$A$5:$A$26,$B20,Gates!$G$5:$G$26,"Pending") -> 7
B21: G2 | C21: Week 13: pilot proven | D21: =COUNTIF(Gates!$A$5:$A$26,B21) -> 6 | E21: =COUNTIFS(Gates!$A$5:$A$26,$B21,Gates!$G$5:$G$26,"Met") -> 0 | F21: =COUNTIFS(Gates!$A$5:$A$26,$B21,Gates!$G$5:$G$26,"Not met") -> 0 | G21: =COUNTIFS(Gates!$A$5:$A$26,$B21,Gates!$G$5:$G$26,"Pending") -> 6
B22: G3 | C22: Week 19-20: term sheet or first close | D22: =COUNTIF(Gates!$A$5:$A$26,B22) -> 3 | E22: =COUNTIFS(Gates!$A$5:$A$26,$B22,Gates!$G$5:$G$26,"Met") -> 0 | F22: =COUNTIFS(Gates!$A$5:$A$26,$B22,Gates!$G$5:$G$26,"Not met") -> 0 | G22: =COUNTIFS(Gates!$A$5:$A$26,$B22,Gates!$G$5:$G$26,"Pending") -> 3
B24: How to use this workbook
B25: Roadmap: every task has an owner designation, a how-to, a deliverable and a cost estimate. Update Status weekly.
B26: Gantt: a visual of the same plan, drawn by formula. Do not type in it.
B27: Gates: four go / no-go checkpoints. Enter actual results in yellow cells.
B28: Roles: designations used as owners, with placeholder salaries. Budget: rolls up cost to the funding gap.
B29: Deck Storyline: slide-by-slide plan for the pitch deck, linked to the evidence you will collect.
B30: Colour code: blue text = input you can change; black = formula; yellow fill = cells you fill in.
B31: Compliance reminder: do not pay unlicensed people for introductions until the legal opinion (Roadmap 0.08) is in hand.
B32: Dependencies matter: the licence (tasks 1.02 to 1.10) is the longest chain and sets the earliest pilot date. Fallback in task 1.17.

Sheet Roadmap
A1: Roadmap: step-by-step plan with owners and milestones
A2: Blue = inputs you can change (start week, duration, cost, owner). Dates recalculate from the project start date on the Overview sheet.
A4: ID | B4: Phase | C4: Workstream | D4: Task / milestone | E4: Type | F4: How to complete (step by step) | G4: Owner (designation) | H4: Support | I4: Start wk | J4: Dur (wks) | K4: End wk | L4: Start date | M4: End date | N4: Depends on | O4: Deliverable / evidence of done | P4: Est. cost AED (excl. salaries) | Q4: Status | R4: Notes / risk
A5: 0.01 | B5: P0 Validate | C5: Strategy | D5: Define wedge, ideal customer and 3 core hypotheses | E5: Task | F5: 1) Pick one first customer (e.g. overseas buyer of AED 1-3m off-plan, or UAE first-time buyer). 2) Write the top 3 problems they have today. 3) List the hypotheses the survey must prove (see Survey workbook, H1-H10). 4) Decide what is in and out of the pilot. | G5: Founder & CEO | H5: Co-founder & CTO | I5: 1 | J5: 1 | K5: =I5+J5-1 -> 1 | L5: =Overview!$C$5+(I5-1)*7 -> 46307 | M5: =L5+(J5-1)*7+4 -> 46311 | N5: - | O5: One-page ICP and hypotheses | P5: 0 | Q5: Not started
A6: 0.02 | B6: P0 Validate | C6: Legal | D6: Founders agreement, vesting and IP assignment | E6: Task | F6: 1) Agree equity split and vesting (e.g. 4 years, 1 year cliff). 2) Sign IP assignment so all code, designs and data belong to the company. 3) Keep signed copies for the data room. | G6: Founder & CEO | H6: Legal Counsel | I6: 1 | J6: 2 | K6: =I6+J6-1 -> 2 | L6: =Overview!$C$5+(I6-1)*7 -> 46307 | M6: =L6+(J6-1)*7+4 -> 46318 | N6: - | O6: Signed founders agreement | P6: 4000 | Q6: Not started | R6: Estimate. Get a fixed-fee quote.
A7: 0.03 | B7: P0 Validate | C7: Evidence | D7: Build the survey and test it with 5 people | E7: Task | F7: 1) Load the questionnaire from the Survey workbook into Google Forms or Typeform. 2) Add the consent text. 3) Test with 5 people, fix unclear questions, check it takes under 10 minutes. | G7: Head of Growth | H7: Data Analyst | I7: 1 | J7: 1 | K7: =I7+J7-1 -> 1 | L7: =Overview!$C$5+(I7-1)*7 -> 46307 | M7: =L7+(J7-1)*7+4 -> 46311 | N7: 0.01 | O7: Live survey link | P7: 0 | Q7: Not started
A8: 0.04 | B8: P0 Validate | C8: Evidence | D8: Run the survey: reach 300+ respondents (50% overseas) | E8: Task | F8: 1) Post in expat and investor WhatsApp, LinkedIn and Facebook groups and relevant subreddits. 2) Ask 20 friends to forward it. 3) Run AED 3,000 of targeted ads to overseas buyers. 4) Offer a small prize draw. 5) Track responses by segment weekly. | G8: Head of Growth | H8: Founder & CEO | I8: 2 | J8: 3 | K8: =I8+J8-1 -> 4 | L8: =Overview!$C$5+(I8-1)*7 -> 46314 | M8: =L8+(J8-1)*7+4 -> 46332 | N8: 0.03 | O8: 300+ responses, segment quotas met | P8: 5000 | Q8: Not started | R8: Ads AED 3,000 + incentive AED 2,000 (estimate).
A9: 0.05 | B9: P0 Validate | C9: Evidence | D9: 30 depth interviews with buyers, investors and tenants | E9: Task | F9: 1) Recruit from survey respondents who opt in. 2) 30-40 minute calls using the interview guide (journey walk-through, last purchase, biggest frustration). 3) Record with consent, tag quotes by hypothesis. | G9: Founder & CEO | H9: Head of Growth | I9: 2 | J9: 3 | K9: =I9+J9-1 -> 4 | L9: =Overview!$C$5+(I9-1)*7 -> 46314 | M9: =L9+(J9-1)*7+4 -> 46332 | N9: 0.03 | O9: 30 interview notes and 10 strong quotes | P9: 1500 | Q9: Not started | R9: Incentives, estimate.
A10: 0.06 | B10: P0 Validate | C10: Evidence | D10: Supply-side interviews: developers, brokerages, designers, furniture brands | E10: Task | F10: 1) Speak to 10 developer sales or channel heads, 5 brokerages, 5 interior designers or furniture brands. 2) Ask about commission, inventory access, online booking, 3D assets. 3) Ask each for a letter of intent. | G10: Partnerships Lead (Developers & Supply) | H10: Founder & CEO | I10: 2 | J10: 3 | K10: =I10+J10-1 -> 4 | L10: =Overview!$C$5+(I10-1)*7 -> 46314 | M10: =L10+(J10-1)*7+4 -> 46332 | N10: 0.01 | O10: 20 interviews logged | P10: 0 | Q10: Not started
A11: 0.07 | B11: P0 Validate | C11: Evidence | D11: Mystery-shop 6 competitors end to end | E11: Task | F11: 1) Go through the buyer journey on Oliva, Huspy, PRYPCO, Property Finder, one developer app and one large brokerage. 2) Screenshot every step, time it and list gaps. 3) Summarise in a 1-page comparison. | G11: Head of Growth | H11: Product Designer | I11: 2 | J11: 2 | K11: =I11+J11-1 -> 3 | L11: =Overview!$C$5+(I11-1)*7 -> 46314 | M11: =L11+(J11-1)*7+4 -> 46325 | N11: - | O11: Competitor teardown | P11: 0 | Q11: Not started
A12: 0.08 | B12: P0 Validate | C12: Legal | D12: Legal opinion: referral model, payments flow, 3D asset rights, data protection | E12: Task | F12: 1) Brief a UAE real estate and fintech lawyer with the model. 2) Ask specifically: can unlicensed residents be paid for introductions, what is the safest structure, can the brokerage route payments to developer escrow, and who owns 3D and floor plan assets. 3) Get the answer in writing. | G12: Legal Counsel | H12: Founder & CEO | I12: 2 | J12: 3 | K12: =I12+J12-1 -> 4 | L12: =Overview!$C$5+(I12-1)*7 -> 46314 | M12: =L12+(J12-1)*7+4 -> 46332 | N12: - | O12: Written legal opinion | P12: 15000 | Q12: Not started | R12: Estimate. Do not launch the resident referral track before this arrives.
A13: 0.09 | B13: P0 Validate | C13: Evidence | D13: Analyse survey and build the problem evidence pack | E13: Task | F13: 1) Export responses into the Survey workbook Responses sheet. 2) Read the Analysis sheet for each hypothesis. 3) Pick the 5 strongest numbers and 5 quotes for the deck. 4) Note weak results honestly. | G13: Data Analyst | H13: Founder & CEO | I13: 5 | J13: 1 | K13: =I13+J13-1 -> 5 | L13: =Overview!$C$5+(I13-1)*7 -> 46335 | M13: =L13+(J13-1)*7+4 -> 46339 | N13: 0.04, 0.05 | O13: Evidence pack (charts and quotes) | P13: 0 | Q13: Not started
A14: 0.10 | B14: P0 Validate | C14: Deck | D14: Pitch deck v1: problem, market, solution, plan | E14: Task | F14: 1) Follow the Deck Storyline sheet slide by slide. 2) Lead with the problem and the survey numbers. 3) Keep to 12-15 slides. 4) Mark pilot-results slides as placeholders. | G14: Founder & CEO | H14: Head of Growth | I14: 3 | J14: 3 | K14: =I14+J14-1 -> 5 | L14: =Overview!$C$5+(I14-1)*7 -> 46321 | M14: =L14+(J14-1)*7+4 -> 46339 | N14: 0.01 | O14: Deck v1 PDF | P14: 0 | Q14: Not started | R14: Start the story in week 3, insert survey numbers in week 5.
A15: 0.11 | B15: P0 Validate | C15: Partnerships | D15: Collect letters of intent: 3 developers, 1 designer, 1 furniture partner | E15: Task | F15: 1) Send a one-page LOI template (non-binding) after each interview. 2) Ask for commission rate, inventory access and 3D asset permission. 3) Follow up weekly. | G15: Partnerships Lead (Developers & Supply) | H15: Founder & CEO | I15: 3 | J15: 4 | K15: =I15+J15-1 -> 6 | L15: =Overview!$C$5+(I15-1)*7 -> 46321 | M15: =L15+(J15-1)*7+4 -> 46346 | N15: 0.06 | O15: 5 signed LOIs | P15: 0 | Q15: Not started
A16: 0.12 | B16: P0 Validate | C16: Deck | D16: Review deck v1 with 3-5 mentors or angels and revise | E16: Task | F16: 1) Send deck with a 3-question feedback form. 2) Hold 20-minute calls. 3) Revise story, numbers and ask. | G16: Founder & CEO | H16: - | I16: 6 | J16: 1 | K16: =I16+J16-1 -> 6 | L16: =Overview!$C$5+(I16-1)*7 -> 46342 | M16: =L16+(J16-1)*7+4 -> 46346 | N16: 0.10 | O16: Deck v1.1 | P16: 0 | Q16: Not started
A17: 0.13 | B17: P0 Validate | C17: Gate | D17: GATE G0: problem and plan validated | E17: Gate | F17: Review the G0 criteria in the Gates sheet. Go only if the survey, interviews, LOIs and legal opinion support the model. If not, adjust the wedge before spending on set-up. | G17: Founder & CEO | H17: Advisors | I17: 6 | J17: 1 | K17: =I17+J17-1 -> 6 | L17: =Overview!$C$5+(I17-1)*7 -> 46342 | M17: =L17+(J17-1)*7+4 -> 46346 | N17: 0.09, 0.11, 0.08 | O17: Go / no-go decision recorded | P17: 0 | Q17: Not started
A18: 1.01 | B18: P1 Set up | C18: Company | D18: Appoint setup consultant (PRO) and confirm entity route | E18: Task | F18: 1) Get 3 fixed-fee quotes. 2) Confirm a Dubai mainland company under DET with the real estate brokerage activity is the right route. 3) Agree scope: DET licence, RERA registration, Ejari, visas. | G18: Founder & CEO | H18: Business Setup Consultant / PRO | I18: 2 | J18: 1 | K18: =I18+J18-1 -> 2 | L18: =Overview!$C$5+(I18-1)*7 -> 46314 | M18: =L18+(J18-1)*7+4 -> 46318 | N18: - | O18: Signed engagement | P18: 5000 | Q18: Not started | R18: Estimate; some packages bundle this.
A19: 1.02 | B19: P1 Set up | C19: People | D19: Hire a RERA-certified Broker-Manager | E19: Task | F19: 1) A licensed manager who has passed the RERA exam must be named for the firm. 2) Source from your network and brokerage recruiters. 3) Agree a role including equity or bonus tied to licence and pilot. | G19: Founder & CEO | H19: Advisors | I19: 2 | J19: 3 | K19: =I19+J19-1 -> 4 | L19: =Overview!$C$5+(I19-1)*7 -> 46314 | M19: =L19+(J19-1)*7+4 -> 46332 | N19: - | O19: Offer letter signed | P19: 0 | Q19: Not started | R19: Long lead item: start now.
A20: 1.03 | B20: P1 Set up | C20: People | D20: Founder and manager complete RERA training (DREI CTREB course) and exam | E20: Task | F20: 1) Book the 4-5 day Certified Training for Real Estate Brokers at the Dubai Real Estate Institute. 2) Sit the RERA exam. 3) Keep certificates for the licence file. | G20: Broker-Manager (Head of Brokerage) | H20: Founder & CEO | I20: 3 | J20: 2 | K20: =I20+J20-1 -> 4 | L20: =Overview!$C$5+(I20-1)*7 -> 46321 | M20: =L20+(J20-1)*7+4 -> 46332 | N20: 1.02 | O20: Exam passed | P20: 9000 | Q20: Not started | R20: Estimate AED 3,000-4,500 per person; skip if already certified.
A21: 1.04 | B21: P1 Set up | C21: Company | D21: Reserve trade name, draft MoA, get DET initial approval | E21: Task | F21: 1) Choose 3 name options. 2) Draft MoA with shareholders and the manager. 3) Submit for initial approval through the PRO. | G21: Business Setup Consultant / PRO | H21: Founder & CEO | I21: 3 | J21: 1 | K21: =I21+J21-1 -> 3 | L21: =Overview!$C$5+(I21-1)*7 -> 46321 | M21: =L21+(J21-1)*7+4 -> 46325 | N21: 1.01 | O21: Initial approval certificate | P21: 0 | Q21: Not started
A22: 1.05 | B22: P1 Set up | C22: Company | D22: Lease a physical office or serviced desk and register Ejari | E22: Task | F22: 1) RERA requires a real commercial address; virtual offices are not accepted. 2) Pick a flexi-desk or serviced office in a commercial building. 3) Get the tenancy contract and register Ejari. | G22: Founder & CEO | H22: Business Setup Consultant / PRO | I22: 3 | J22: 2 | K22: =I22+J22-1 -> 4 | L22: =Overview!$C$5+(I22-1)*7 -> 46321 | M22: =L22+(J22-1)*7+4 -> 46332 | N22: 1.01 | O22: Tenancy contract and Ejari | P22: 25000 | Q22: Not started | R22: Estimate AED 15,000-40,000 per year.
A23: 1.06 | B23: P1 Set up | C23: Company | D23: Issue DET trade licence (real estate brokerage activity) | E23: Task | F23: 1) PRO submits MoA, lease and approvals. 2) Pay licence fees. 3) Collect licence and establishment card. | G23: Business Setup Consultant / PRO | H23: Founder & CEO | I23: 4 | J23: 2 | K23: =I23+J23-1 -> 5 | L23: =Overview!$C$5+(I23-1)*7 -> 46328 | M23: =L23+(J23-1)*7+4 -> 46339 | N23: 1.04, 1.05 | O23: Trade licence | P23: 15000 | Q23: Not started | R23: Estimate AED 12,000-15,000.
A24: 1.07 | B24: P1 Set up | C24: Finance | D24: Open corporate bank account and deposit share capital | E24: Task | F24: 1) Start bank onboarding as soon as the licence is issued. 2) Deposit the minimum capital (starts at AED 100,000 for a standard brokerage). 3) Set up payment and card access. | G24: Fractional CFO | H24: Founder & CEO | I24: 5 | J24: 2 | K24: =I24+J24-1 -> 6 | L24: =Overview!$C$5+(I24-1)*7 -> 46335 | M24: =L24+(J24-1)*7+4 -> 46346 | N24: 1.06 | O24: Active bank account | P24: 0 | Q24: Not started | R24: Capital is not an expense; see Budget sheet.
A25: 1.08 | B25: P1 Set up | C25: Regulatory | D25: Register the brokerage with RERA / DLD (Trakheesi) | E25: Task | F25: 1) Register the company as an authorised brokerage in Trakheesi once the DET licence is active and principals hold broker cards. 2) Pay the registration fee. 3) Get access to ad permits. | G25: Broker-Manager (Head of Brokerage) | H25: Business Setup Consultant / PRO | I25: 5 | J25: 2 | K25: =I25+J25-1 -> 6 | L25: =Overview!$C$5+(I25-1)*7 -> 46335 | M25: =L25+(J25-1)*7+4 -> 46346 | N25: 1.03, 1.06 | O25: RERA brokerage registration | P25: 8000 | Q25: Not started | R25: Estimate AED 5,000-10,000.
A26: 1.09 | B26: P1 Set up | C26: Regulatory | D26: Issue broker cards for the manager and pilot agents | E26: Task | F26: 1) Each agent completes training and the exam. 2) Apply through Trakheesi under the firm. 3) Cards are valid for a set period and must be renewed. | G26: Broker-Manager (Head of Brokerage) | H26: Business Setup Consultant / PRO | I26: 5 | J26: 2 | K26: =I26+J26-1 -> 6 | L26: =Overview!$C$5+(I26-1)*7 -> 46335 | M26: =L26+(J26-1)*7+4 -> 46346 | N26: 1.03 | O26: At least 2 valid broker cards | P26: 15000 | Q26: Not started | R26: Estimate ~AED 5,000 per card.
A27: 1.10 | B27: P1 Set up | C27: Compliance | D27: Register on goAML, appoint compliance officer, write AML/KYC policy | E27: Task | F27: 1) Brokers are DNFBPs under the UAE AML law. 2) Register on goAML. 3) Appoint a compliance officer. 4) Write a risk-based KYC policy: ID checks, source of funds, sanctions screening, reporting of cash AED 55,000+ and any virtual asset payment. | G27: Compliance & AML Officer | H27: Legal Counsel | I27: 5 | J27: 3 | K27: =I27+J27-1 -> 7 | L27: =Overview!$C$5+(I27-1)*7 -> 46335 | M27: =L27+(J27-1)*7+4 -> 46353 | N27: 1.06 | O27: goAML account and approved policy | P27: 5000 | Q27: Not started | R27: Estimate for policy drafting.
A28: 1.11 | B28: P1 Set up | C28: Compliance | D28: Policies and templates: Forms A/B, commission agreements, T&Cs, privacy, complaints | E28: Task | F28: 1) Use RERA standard forms where required. 2) Draft customer T&Cs, privacy notice (PDPL), referral terms and complaints process. 3) Lawyer review. | G28: Legal Counsel | H28: Compliance & AML Officer | I28: 5 | J28: 3 | K28: =I28+J28-1 -> 7 | L28: =Overview!$C$5+(I28-1)*7 -> 46335 | M28: =L28+(J28-1)*7+4 -> 46353 | N28: 0.08 | O28: Approved template pack | P28: 5000 | Q28: Not started | R28: Estimate.
A29: 1.12 | B29: P1 Set up | C29: Compliance | D29: Professional indemnity and trade insurance | E29: Task | F29: 1) Get 3 quotes. 2) Choose cover for errors and omissions and general liability. 3) Keep the certificate for developers and investors. | G29: Fractional CFO | H29: Broker-Manager (Head of Brokerage) | I29: 6 | J29: 2 | K29: =I29+J29-1 -> 7 | L29: =Overview!$C$5+(I29-1)*7 -> 46342 | M29: =L29+(J29-1)*7+4 -> 46353 | N29: 1.06 | O29: Insurance certificate | P29: 6000 | Q29: Not started | R29: Estimate.
A30: 1.13 | B30: P1 Set up | C30: Partnerships | D30: Sign developer broker agreements (3-5) and get portal access | E30: Task | F30: 1) Convert LOIs into broker agreements. 2) Get access to sales portals and live price lists. 3) Confirm commission rate and payout timing in writing. | G30: Partnerships Lead (Developers & Supply) | H30: Broker-Manager (Head of Brokerage) | I30: 5 | J30: 4 | K30: =I30+J30-1 -> 8 | L30: =Overview!$C$5+(I30-1)*7 -> 46335 | M30: =L30+(J30-1)*7+4 -> 46360 | N30: 0.11, 1.08 | O30: 3+ signed agreements | P30: 0 | Q30: Not started | R30: Needs RERA registration to finish.
A31: 1.14 | B31: P1 Set up | C31: Operations | D31: Payment flow: route to developer escrow / trustee, brokerage never holds client funds | E31: Task | F31: 1) Map each payment type (booking, instalments, DLD fee, trustee fee). 2) Confirm with the lawyer who holds what. 3) Pick a licensed payment partner for platform fees only. | G31: Founder & CEO | H31: Legal Counsel | I31: 6 | J31: 2 | K31: =I31+J31-1 -> 7 | L31: =Overview!$C$5+(I31-1)*7 -> 46342 | M31: =L31+(J31-1)*7+4 -> 46353 | N31: 0.08 | O31: Approved payment flow diagram | P31: 0 | Q31: Not started
A32: 1.15 | B32: P1 Set up | C32: Operations | D32: Set up Trakheesi permit and Madmoun QR workflow for pilot listings | E32: Task | F32: 1) Create one permit per listed unit. 2) Add the QR to every ad and unit page. 3) Delist within 3 working days of a sale or rental. | G32: Broker-Manager (Head of Brokerage) | H32: Co-founder & CTO | I32: 7 | J32: 1 | K32: =I32+J32-1 -> 7 | L32: =Overview!$C$5+(I32-1)*7 -> 46349 | M32: =L32+(J32-1)*7+4 -> 46353 | N32: 1.08 | O32: Permit workflow tested | P32: 0 | Q32: Not started
A33: 1.16 | B33: P1 Set up | C33: Milestone | D33: MILESTONE M1: brokerage licensed and operating | E33: Milestone | F33: DET licence issued, RERA registration done, broker cards held, goAML registered. If not done by week 8, trigger task 1.17. | G33: Founder & CEO | H33: Broker-Manager (Head of Brokerage) | I33: 8 | J33: 1 | K33: =I33+J33-1 -> 8 | L33: =Overview!$C$5+(I33-1)*7 -> 46356 | M33: =L33+(J33-1)*7+4 -> 46360 | N33: 1.06, 1.08, 1.09, 1.10 | O33: Licence pack in data room | P33: 0 | Q33: Not started
A34: 1.17 | B34: P1 Set up | C34: Contingency | D34: If licence is late: run the pilot through a licensed partner brokerage | E34: Task | F34: 1) Decision point at week 8. 2) Only after the lawyer confirms the structure, run the pilot as co-brokerage with a licensed firm. 3) Move to your own licence once issued. | G34: Founder & CEO | H34: Legal Counsel | I34: 8 | J34: 1 | K34: =I34+J34-1 -> 8 | L34: =Overview!$C$5+(I34-1)*7 -> 46356 | M34: =L34+(J34-1)*7+4 -> 46360 | N34: 1.16 | O34: Decision recorded | P34: 0 | Q34: Not started | R34: Fallback to protect the pilot date.
A35: 2.01 | B35: P2 Pilot | C35: Product | D35: Define pilot scope, target segment and success metrics | E35: Task | F35: 1) Choose 1 segment and 3 developers. 2) Set targets (see G2 in the Gates sheet). 3) Decide what is manual behind the scenes. | G35: Founder & CEO | H35: Head of Growth | I35: 5 | J35: 1 | K35: =I35+J35-1 -> 5 | L35: =Overview!$C$5+(I35-1)*7 -> 46335 | M35: =L35+(J35-1)*7+4 -> 46339 | N35: 0.13 | O35: Pilot charter | P35: 0 | Q35: Not started
A36: 2.02 | B36: P2 Pilot | C36: Product | D36: Clickable prototype of the core journey (insights, 3D, reserve, tracker) | E36: Task | F36: 1) Design 12-15 screens in Figma. 2) Link them into a clickable flow. 3) Use it in investor and user meetings. | G36: Co-founder & CTO | H36: Product Designer | I36: 4 | J36: 3 | K36: =I36+J36-1 -> 6 | L36: =Overview!$C$5+(I36-1)*7 -> 46328 | M36: =L36+(J36-1)*7+4 -> 46346 | N36: 0.01 | O36: Figma prototype | P36: 6000 | Q36: Not started | R36: Estimate.
A37: 2.03 | B37: P2 Pilot | C37: Product | D37: Test the prototype with 10 users and iterate | E37: Task | F37: 1) Run 30-minute sessions. 2) Measure task success and time. 3) Fix the top 5 issues. | G37: Product Designer | H37: Head of Growth | I37: 7 | J37: 1 | K37: =I37+J37-1 -> 7 | L37: =Overview!$C$5+(I37-1)*7 -> 46349 | M37: =L37+(J37-1)*7+4 -> 46353 | N37: 2.02 | O37: Test report | P37: 0 | Q37: Not started
A38: 2.04 | B38: P2 Pilot | C38: Product | D38: Insights v0: data sources and 5 insight cards | E38: Task | F38: 1) Source Dubai Land Department open data and get a quote for a licensed data feed. 2) Build 5 cards: price per sq ft trend, rental yield, supply pipeline, developer delivery record, service charge. 3) Show data source and date on every card. | G38: Data Analyst | H38: Co-founder & CTO | I38: 5 | J38: 4 | K38: =I38+J38-1 -> 8 | L38: =Overview!$C$5+(I38-1)*7 -> 46335 | M38: =L38+(J38-1)*7+4 -> 46360 | N38: 0.01 | O38: 5 live insight cards | P38: 10000 | Q38: Not started | R38: Estimate for data licence.
A39: 2.05 | B39: P2 Pilot | C39: Product | D39: 3D / virtual tour for 10 units via developer assets or a viewer partner | E39: Task | F39: 1) Ask developers for their 3D and floor plan files. 2) Get written permission to display them. 3) Embed a viewer. 4) Do not build in-house 3D for the pilot. | G39: Partnerships Lead (Developers & Supply) | H39: Co-founder & CTO | I39: 6 | J39: 3 | K39: =I39+J39-1 -> 8 | L39: =Overview!$C$5+(I39-1)*7 -> 46342 | M39: =L39+(J39-1)*7+4 -> 46360 | N39: 1.13 | O39: 10 units with 3D view and signed asset permission | P39: 8000 | Q39: Not started | R39: Estimate.
A40: 2.06 | B40: P2 Pilot | C40: Product | D40: Documents and payment reminders v0 | E40: Task | F40: 1) Build a checklist per deal type (off-plan, ready, rent). 2) Add a document vault. 3) Send reminders for instalments and registrations by email or WhatsApp. 4) Use no-code tools and a contractor first. | G40: Co-founder & CTO | H40: Product Designer | I40: 6 | J40: 3 | K40: =I40+J40-1 -> 8 | L40: =Overview!$C$5+(I40-1)*7 -> 46342 | M40: =L40+(J40-1)*7+4 -> 46360 | N40: 0.01 | O40: Working tracker for 5 test deals | P40: 12000 | Q40: Not started | R40: Estimate.
A41: 2.07 | B41: P2 Pilot | C41: Partnerships | D41: Furniture and interior designer pilot with 1 designer and 1 retailer | E41: Task | F41: 1) Agree an affiliate or booking-fee deal. 2) Add a simple "design my unit" request form. 3) Do not build augmented reality design tools yet. | G41: Partnerships Lead (Developers & Supply) | H41: Co-founder & CTO | I41: 7 | J41: 3 | K41: =I41+J41-1 -> 9 | L41: =Overview!$C$5+(I41-1)*7 -> 46349 | M41: =L41+(J41-1)*7+4 -> 46367 | N41: 0.11 | O41: Partner terms and landing page | P41: 2000 | Q41: Not started | R41: Estimate.
...

Sheet Gantt
A1: Gantt: 20-week view
A2: Bars are drawn by formula from Start wk and Dur on the Roadmap sheet. Colour = phase.
F3: Week | G3: 1 | H3: 2 | I3: 3 | J3: 4 | K3: 5 | L3: 6 | M3: 7 | N3: 8 | O3: 9 | P3: 10 | Q3: 11 | R3: 12 | S3: 13 | T3: 14 | U3: 15 | V3: 16 | W3: 17 | X3: 18 | Y3: 19 | Z3: 20
A4: ID | B4: Phase | C4: Task | D4: Owner | E4: Start wk | F4: End wk | G4: =Overview!$C$5+(G$3-1)*7 -> 46307 | H4: =Overview!$C$5+(H$3-1)*7 -> 46314 | I4: =Overview!$C$5+(I$3-1)*7 -> 46321 | J4: =Overview!$C$5+(J$3-1)*7 -> 46328 | K4: =Overview!$C$5+(K$3-1)*7 -> 46335 | L4: =Overview!$C$5+(L$3-1)*7 -> 46342 | M4: =Overview!$C$5+(M$3-1)*7 -> 46349 | N4: =Overview!$C$5+(N$3-1)*7 -> 46356 | ... Z4: =Overview!$C$5+(Z$3-1)*7 -> 46440
A5: =Roadmap!A5 -> 0.01 | B5: =Roadmap!B5 -> P0 Validate | C5: =Roadmap!D5 -> Define wedge, ideal customer and 3 core hypotheses | D5: =Roadmap!G5 -> Founder & CEO | E5: =Roadmap!I5 -> 1 | F5: =Roadmap!K5 -> 1 | G5: =IF(AND(G$3>=$E5,G$3<=$F5),1,"") -> 1 | H5: =IF(AND(H$3>=$E5,H$3<=$F5),1,"") | I5: =IF(AND(I$3>=$E5,I$3<=$F5),1,"") | J5: =IF(AND(J$3>=$E5,J$3<=$F5),1,"") | K5: =IF(AND(K$3>=$E5,K$3<=$F5),1,"") | L5: =IF(AND(L$3>=$E5,L$3<=$F5),1,"") | M5: =IF(AND(M$3>=$E5,M$3<=$F5),1,"") | N5: =IF(AND(N$3>=$E5,N$3<=$F5),1,"") | ... Z5: =IF(AND(Z$3>=$E5,Z$3<=$F5),1,"")
A6: =Roadmap!A6 -> 0.02 | B6: =Roadmap!B6 -> P0 Validate | C6: =Roadmap!D6 -> Founders agreement, vesting and IP assignment | D6: =Roadmap!G6 -> Founder & CEO | E6: =Roadmap!I6 -> 1 | F6: =Roadmap!K6 -> 2 | G6: =IF(AND(G$3>=$E6,G$3<=$F6),1,"") -> 1 | H6: =IF(AND(H$3>=$E6,H$3<=$F6),1,"") -> 1 | I6: =IF(AND(I$3>=$E6,I$3<=$F6),1,"") | J6: =IF(AND(J$3>=$E6,J$3<=$F6),1,"") | K6: =IF(AND(K$3>=$E6,K$3<=$F6),1,"") | L6: =IF(AND(L$3>=$E6,L$3<=$F6),1,"") | M6: =IF(AND(M$3>=$E6,M$3<=$F6),1,"") | N6: =IF(AND(N$3>=$E6,N$3<=$F6),1,"") | ... Z6: =IF(AND(Z$3>=$E6,Z$3<=$F6),1,"")
A7: =Roadmap!A7 -> 0.03 | B7: =Roadmap!B7 -> P0 Validate | C7: =Roadmap!D7 -> Build the survey and test it with 5 people | D7: =Roadmap!G7 -> Head of Growth | E7: =Roadmap!I7 -> 1 | F7: =Roadmap!K7 -> 1 | G7: =IF(AND(G$3>=$E7,G$3<=$F7),1,"") -> 1 | H7: =IF(AND(H$3>=$E7,H$3<=$F7),1,"") | I7: =IF(AND(I$3>=$E7,I$3<=$F7),1,"") | J7: =IF(AND(J$3>=$E7,J$3<=$F7),1,"") | K7: =IF(AND(K$3>=$E7,K$3<=$F7),1,"") | L7: =IF(AND(L$3>=$E7,L$3<=$F7),1,"") | M7: =IF(AND(M$3>=$E7,M$3<=$F7),1,"") | N7: =IF(AND(N$3>=$E7,N$3<=$F7),1,"") | ... Z7: =IF(AND(Z$3>=$E7,Z$3<=$F7),1,"")
A8: =Roadmap!A8 -> 0.04 | B8: =Roadmap!B8 -> P0 Validate | C8: =Roadmap!D8 -> Run the survey: reach 300+ respondents (50% overseas) | D8: =Roadmap!G8 -> Head of Growth | E8: =Roadmap!I8 -> 2 | F8: =Roadmap!K8 -> 4 | G8: =IF(AND(G$3>=$E8,G$3<=$F8),1,"") | H8: =IF(AND(H$3>=$E8,H$3<=$F8),1,"") -> 1 | I8: =IF(AND(I$3>=$E8,I$3<=$F8),1,"") -> 1 | J8: =IF(AND(J$3>=$E8,J$3<=$F8),1,"") -> 1 | K8: =IF(AND(K$3>=$E8,K$3<=$F8),1,"") | L8: =IF(AND(L$3>=$E8,L$3<=$F8),1,"") | M8: =IF(AND(M$3>=$E8,M$3<=$F8),1,"") | N8: =IF(AND(N$3>=$E8,N$3<=$F8),1,"") | ... Z8: =IF(AND(Z$3>=$E8,Z$3<=$F8),1,"")
A9: =Roadmap!A9 -> 0.05 | B9: =Roadmap!B9 -> P0 Validate | C9: =Roadmap!D9 -> 30 depth interviews with buyers, investors and tenants | D9: =Roadmap!G9 -> Founder & CEO | E9: =Roadmap!I9 -> 2 | F9: =Roadmap!K9 -> 4 | G9: =IF(AND(G$3>=$E9,G$3<=$F9),1,"") | H9: =IF(AND(H$3>=$E9,H$3<=$F9),1,"") -> 1 | I9: =IF(AND(I$3>=$E9,I$3<=$F9),1,"") -> 1 | J9: =IF(AND(J$3>=$E9,J$3<=$F9),1,"") -> 1 | K9: =IF(AND(K$3>=$E9,K$3<=$F9),1,"") | L9: =IF(AND(L$3>=$E9,L$3<=$F9),1,"") | M9: =IF(AND(M$3>=$E9,M$3<=$F9),1,"") | N9: =IF(AND(N$3>=$E9,N$3<=$F9),1,"") | ... Z9: =IF(AND(Z$3>=$E9,Z$3<=$F9),1,"")
A10: =Roadmap!A10 -> 0.06 | B10: =Roadmap!B10 -> P0 Validate | C10: =Roadmap!D10 -> Supply-side interviews: developers, brokerages, designers, furniture brands | D10: =Roadmap!G10 -> Partnerships Lead (Developers & Supply) | E10: =Roadmap!I10 -> 2 | F10: =Roadmap!K10 -> 4 | G10: =IF(AND(G$3>=$E10,G$3<=$F10),1,"") | H10: =IF(AND(H$3>=$E10,H$3<=$F10),1,"") -> 1 | I10: =IF(AND(I$3>=$E10,I$3<=$F10),1,"") -> 1 | J10: =IF(AND(J$3>=$E10,J$3<=$F10),1,"") -> 1 | K10: =IF(AND(K$3>=$E10,K$3<=$F10),1,"") | L10: =IF(AND(L$3>=$E10,L$3<=$F10),1,"") | M10: =IF(AND(M$3>=$E10,M$3<=$F10),1,"") | N10: =IF(AND(N$3>=$E10,N$3<=$F10),1,"") | ... Z10: =IF(AND(Z$3>=$E10,Z$3<=$F10),1,"")
A11: =Roadmap!A11 -> 0.07 | B11: =Roadmap!B11 -> P0 Validate | C11: =Roadmap!D11 -> Mystery-shop 6 competitors end to end | D11: =Roadmap!G11 -> Head of Growth | E11: =Roadmap!I11 -> 2 | F11: =Roadmap!K11 -> 3 | G11: =IF(AND(G$3>=$E11,G$3<=$F11),1,"") | H11: =IF(AND(H$3>=$E11,H$3<=$F11),1,"") -> 1 | I11: =IF(AND(I$3>=$E11,I$3<=$F11),1,"") -> 1 | J11: =IF(AND(J$3>=$E11,J$3<=$F11),1,"") | K11: =IF(AND(K$3>=$E11,K$3<=$F11),1,"") | L11: =IF(AND(L$3>=$E11,L$3<=$F11),1,"") | M11: =IF(AND(M$3>=$E11,M$3<=$F11),1,"") | N11: =IF(AND(N$3>=$E11,N$3<=$F11),1,"") | ... Z11: =IF(AND(Z$3>=$E11,Z$3<=$F11),1,"")
A12: =Roadmap!A12 -> 0.08 | B12: =Roadmap!B12 -> P0 Validate | C12: =Roadmap!D12 -> Legal opinion: referral model, payments flow, 3D asset rights, data protection | D12: =Roadmap!G12 -> Legal Counsel | E12: =Roadmap!I12 -> 2 | F12: =Roadmap!K12 -> 4 | G12: =IF(AND(G$3>=$E12,G$3<=$F12),1,"") | H12: =IF(AND(H$3>=$E12,H$3<=$F12),1,"") -> 1 | I12: =IF(AND(I$3>=$E12,I$3<=$F12),1,"") -> 1 | J12: =IF(AND(J$3>=$E12,J$3<=$F12),1,"") -> 1 | K12: =IF(AND(K$3>=$E12,K$3<=$F12),1,"") | L12: =IF(AND(L$3>=$E12,L$3<=$F12),1,"") | M12: =IF(AND(M$3>=$E12,M$3<=$F12),1,"") | N12: =IF(AND(N$3>=$E12,N$3<=$F12),1,"") | ... Z12: =IF(AND(Z$3>=$E12,Z$3<=$F12),1,"")
A13: =Roadmap!A13 -> 0.09 | B13: =Roadmap!B13 -> P0 Validate | C13: =Roadmap!D13 -> Analyse survey and build the problem evidence pack | D13: =Roadmap!G13 -> Data Analyst | E13: =Roadmap!I13 -> 5 | F13: =Roadmap!K13 -> 5 | G13: =IF(AND(G$3>=$E13,G$3<=$F13),1,"") | H13: =IF(AND(H$3>=$E13,H$3<=$F13),1,"") | I13: =IF(AND(I$3>=$E13,I$3<=$F13),1,"") | J13: =IF(AND(J$3>=$E13,J$3<=$F13),1,"") | K13: =IF(AND(K$3>=$E13,K$3<=$F13),1,"") -> 1 | L13: =IF(AND(L$3>=$E13,L$3<=$F13),1,"") | M13: =IF(AND(M$3>=$E13,M$3<=$F13),1,"") | N13: =IF(AND(N$3>=$E13,N$3<=$F13),1,"") | ... Z13: =IF(AND(Z$3>=$E13,Z$3<=$F13),1,"")
A14: =Roadmap!A14 -> 0.10 | B14: =Roadmap!B14 -> P0 Validate | C14: =Roadmap!D14 -> Pitch deck v1: problem, market, solution, plan | D14: =Roadmap!G14 -> Founder & CEO | E14: =Roadmap!I14 -> 3 | F14: =Roadmap!K14 -> 5 | G14: =IF(AND(G$3>=$E14,G$3<=$F14),1,"") | H14: =IF(AND(H$3>=$E14,H$3<=$F14),1,"") | I14: =IF(AND(I$3>=$E14,I$3<=$F14),1,"") -> 1 | J14: =IF(AND(J$3>=$E14,J$3<=$F14),1,"") -> 1 | K14: =IF(AND(K$3>=$E14,K$3<=$F14),1,"") -> 1 | L14: =IF(AND(L$3>=$E14,L$3<=$F14),1,"") | M14: =IF(AND(M$3>=$E14,M$3<=$F14),1,"") | N14: =IF(AND(N$3>=$E14,N$3<=$F14),1,"") | ... Z14: =IF(AND(Z$3>=$E14,Z$3<=$F14),1,"")
A15: =Roadmap!A15 -> 0.11 | B15: =Roadmap!B15 -> P0 Validate | C15: =Roadmap!D15 -> Collect letters of intent: 3 developers, 1 designer, 1 furniture partner | D15: =Roadmap!G15 -> Partnerships Lead (Developers & Supply) | E15: =Roadmap!I15 -> 3 | F15: =Roadmap!K15 -> 6 | G15: =IF(AND(G$3>=$E15,G$3<=$F15),1,"") | H15: =IF(AND(H$3>=$E15,H$3<=$F15),1,"") | I15: =IF(AND(I$3>=$E15,I$3<=$F15),1,"") -> 1 | J15: =IF(AND(J$3>=$E15,J$3<=$F15),1,"") -> 1 | K15: =IF(AND(K$3>=$E15,K$3<=$F15),1,"") -> 1 | L15: =IF(AND(L$3>=$E15,L$3<=$F15),1,"") -> 1 | M15: =IF(AND(M$3>=$E15,M$3<=$F15),1,"") | N15: =IF(AND(N$3>=$E15,N$3<=$F15),1,"") | ... Z15: =IF(AND(Z$3>=$E15,Z$3<=$F15),1,"")
A16: =Roadmap!A16 -> 0.12 | B16: =Roadmap!B16 -> P0 Validate | C16: =Roadmap!D16 -> Review deck v1 with 3-5 mentors or angels and revise | D16: =Roadmap!G16 -> Founder & CEO | E16: =Roadmap!I16 -> 6 | F16: =Roadmap!K16 -> 6 | G16: =IF(AND(G$3>=$E16,G$3<=$F16),1,"") | H16: =IF(AND(H$3>=$E16,H$3<=$F16),1,"") | I16: =IF(AND(I$3>=$E16,I$3<=$F16),1,"") | J16: =IF(AND(J$3>=$E16,J$3<=$F16),1,"") | K16: =IF(AND(K$3>=$E16,K$3<=$F16),1,"") | L16: =IF(AND(L$3>=$E16,L$3<=$F16),1,"") -> 1 | M16: =IF(AND(M$3>=$E16,M$3<=$F16),1,"") | N16: =IF(AND(N$3>=$E16,N$3<=$F16),1,"") | ... Z16: =IF(AND(Z$3>=$E16,Z$3<=$F16),1,"")
... A59: =Roadmap!A59 -> 3.08 | B59: =Roadmap!B59 -> P3 Raise | C59: =Roadmap!D59 -> GATE G3: term sheet or first close | D59: =Roadmap!G59 -> Founder & CEO | E59: =Roadmap!I59 -> 19 | F59: =Roadmap!K59 -> 20 | G59: =IF(AND(G$3>=$E59,G$3<=$F59),1,"") | H59: =IF(AND(H$3>=$E59,H$3<=$F59),1,"") | I59: =IF(AND(I$3>=$E59,I$3<=$F59),1,"") | J59: =IF(AND(J$3>=$E59,J$3<=$F59),1,"") | K59: =IF(AND(K$3>=$E59,K$3<=$F59),1,"") | L59: =IF(AND(L$3>=$E59,L$3<=$F59),1,"") | M59: =IF(AND(M$3>=$E59,M$3<=$F59),1,"") | N59: =IF(AND(N$3>=$E59,N$3<=$F59),1,"") | ... Z59: =IF(AND(Z$3>=$E59,Z$3<=$F59),1,"") -> 1

Sheet Gates
A1: Gates: investor-facing go / no-go criteria
A2: Targets are suggestions (blue). Enter actual results in the yellow cells; Status updates by formula.
A4: Gate | B4: Stage | C4: Criterion | D4: Test | E4: Target | F4: Actual (enter) | G4: Status | H4: Evidence source
A5: G0 | B5: Week 6: problem and plan validated | C5: Survey responses collected | D5: >= | E5: 300 | G5: =IF(F5="","Pending",IF(D5=">=",IF(F5>=E5,"Met","Not met"),IF(F5<=E5,"Met","Not met"))) -> Pending | H5: Survey export row count
A6: G0 | B6: Week 6: problem and plan validated | C6: Respondents rating reliable information or verification as hard (4-5), % | D6: >= | E6: 0.6 | G6: =IF(F6="","Pending",IF(D6=">=",IF(F6>=E6,"Met","Not met"),IF(F6<=E6,"Met","Not met"))) -> Pending | H6: Survey Analysis sheet, H1
A7: G0 | B7: Week 6: problem and plan validated | C7: Depth interviews completed | D7: >= | E7: 30 | G7: =IF(F7="","Pending",IF(D7=">=",IF(F7>=E7,"Met","Not met"),IF(F7<=E7,"Met","Not met"))) -> Pending | H7: Interview notes
A8: G0 | B8: Week 6: problem and plan validated | C8: Letters of intent from developers | D8: >= | E8: 3 | G8: =IF(F8="","Pending",IF(D8=">=",IF(F8>=E8,"Met","Not met"),IF(F8<=E8,"Met","Not met"))) -> Pending | H8: Signed LOIs
A9: G0 | B9: Week 6: problem and plan validated | C9: Written legal opinion received (1 = yes) | D9: >= | E9: 1 | G9: =IF(F9="","Pending",IF(D9=">=",IF(F9>=E9,"Met","Not met"),IF(F9<=E9,"Met","Not met"))) -> Pending | H9: Law firm letter
A10: G0 | B10: Week 6: problem and plan validated | C10: Mentors who reviewed deck v1 | D10: >= | E10: 3 | G10: =IF(F10="","Pending",IF(D10=">=",IF(F10>=E10,"Met","Not met"),IF(F10<=E10,"Met","Not met"))) -> Pending | H10: Feedback forms
A11: G1 | B11: Week 8: licensed and pilot-ready | C11: DET trade licence issued (1 = yes) | D11: >= | E11: 1 | G11: =IF(F11="","Pending",IF(D11=">=",IF(F11>=E11,"Met","Not met"),IF(F11<=E11,"Met","Not met"))) -> Pending | H11: Licence copy
A12: G1 | B12: Week 8: licensed and pilot-ready | C12: RERA brokerage registration done (1 = yes) | D12: >= | E12: 1 | G12: =IF(F12="","Pending",IF(D12=">=",IF(F12>=E12,"Met","Not met"),IF(F12<=E12,"Met","Not met"))) -> Pending | H12: Trakheesi record
A13: G1 | B13: Week 8: licensed and pilot-ready | C13: Valid broker cards held | D13: >= | E13: 2 | G13: =IF(F13="","Pending",IF(D13=">=",IF(F13>=E13,"Met","Not met"),IF(F13<=E13,"Met","Not met"))) -> Pending | H13: Card copies
A14: G1 | B14: Week 8: licensed and pilot-ready | C14: goAML registered, AML policy approved (1 = yes) | D14: >= | E14: 1 | G14: =IF(F14="","Pending",IF(D14=">=",IF(F14>=E14,"Met","Not met"),IF(F14<=E14,"Met","Not met"))) -> Pending | H14: goAML confirmation
A15: G1 | B15: Week 8: licensed and pilot-ready | C15: Signed developer agreements | D15: >= | E15: 3 | G15: =IF(F15="","Pending",IF(D15=">=",IF(F15>=E15,"Met","Not met"),IF(F15<=E15,"Met","Not met"))) -> Pending | H15: Agreements
A16: G1 | B16: Week 8: licensed and pilot-ready | C16: Units live with permits | D16: >= | E16: 150 | G16: =IF(F16="","Pending",IF(D16=">=",IF(F16>=E16,"Met","Not met"),IF(F16<=E16,"Met","Not met"))) -> Pending | H16: Inventory sheet
... A26: G3 | B26: Week 19-20: term sheet or first close | C26: Term sheets received | D26: >= | E26: 1 | G26: =IF(F26="","Pending",IF(D26=">=",IF(F26>=E26,"Met","Not met"),IF(F26<=E26,"Met","Not met"))) -> Pending | H26: Investor CRM
C28: Example (not counted): Survey responses collected; Target 300; Actual 312 -> Status shows "Met".

Sheet Roles
A1: Roles and owners
A2: Owner designations used in the Roadmap. Salaries are placeholders (assumptions) to be replaced with real quotes. External firms are costed in Roadmap tasks, not here.
A4: Designation | B4: Type | C4: Key responsibilities | D4: Must hold | E4: Needed from week | F4: Monthly cost AED (assumption) | G4: Months in plan (to wk 13) | H4: Total AED
A5: Founder & CEO | B5: Founder | C5: Vision, fundraising, investor relations, legal/entity decisions, final owner of pitch deck and gates | D5: Broker card if acting as licensed manager (optional) | E5: 1 | F5: 0 | G5: 3 | H5: =F5*G5 -> 0
A6: Co-founder & CTO | B6: Founder | C6: Product, tech architecture, MVP build, data and security | D6: - | E6: 1 | F6: 0 | G6: 3 | H6: =F6*G6 -> 0
A7: Broker-Manager (Head of Brokerage) | B7: Hire | C7: Licensed manager named on the RERA registration; runs deals, agent compliance, Form A/B/F handling, Trakheesi permits | D7: RERA broker card + passed RERA exam (CTREB) | E7: 2 | F7: 22000 | G7: 3 | H7: =F7*G7 -> 66000
A8: Compliance & AML Officer | B8: Fractional hire | C8: goAML registration, KYC/AML policy, suspicious transaction and cash (AED 55k+) reporting, PDPL data protection | D8: AML/CFT training; registered with MoET as DNFBP | E8: 5 | F8: 6000 | G8: 3 | H8: =F8*G8 -> 18000
A9: Head of Growth | B9: Hire | C9: Survey, lead generation, referral programme, paid and community channels, CAC tracking | D9: - | E9: 1 | F9: 12000 | G9: 3 | H9: =F9*G9 -> 36000
A10: Partnerships Lead (Developers & Supply) | B10: Hire | C10: Developer agreements, inventory feeds, 3D asset rights, designer and furniture partners | D10: - | E10: 2 | F10: 15000 | G10: 3 | H10: =F10*G10 -> 45000
A11: Product Designer | B11: Freelance | C11: Prototype, user tests, UI for insights, 3D viewer, tracker | D11: - | E11: 4 | F11: 8000 | G11: 2 | H11: =F11*G11 -> 16000
A12: Data Analyst | B12: Freelance / part-time | C12: Survey analysis, insights engine v0, pilot KPI dashboard | D12: - | E12: 5 | F12: 8000 | G12: 3 | H12: =F12*G12 -> 24000
A13: Fractional CFO | B13: Fractional | C13: Budget, financial model, cap table, data room, investor Q&A | D13: - | E13: 7 | F13: 5000 | G13: 3 | H13: =F13*G13 -> 15000
A14: Licensed Sales Agents (x2) | B14: Hire (pilot) | C14: Close pilot deals under the brokerage; follow scripts and compliance rules | D14: RERA broker card each | E14: 8 | F14: 10000 | G14: 2 | H14: =F14*G14 -> 20000
A15: Legal Counsel | B15: External law firm | C15: Legal opinion on referral model and payments flow, templates, T&Cs, PDPL, cap table docs | D15: UAE-qualified | E15: 2 | F15: 0 | G15: 0 | H15: =F15*G15 -> 0
A16: Business Setup Consultant / PRO | B16: External | C16: DET trade licence, RERA registration, Ejari, visas, government portals | D16: - | E16: 2 | F16: 0 | G16: 0 | H16: =F16*G16 -> 0
G17: Total people cost | H17: =SUM(H5:H16) -> 240000
A19: Assumption: founders take no salary during the pilot. Replace with your own numbers; blue = input.

Sheet Budget
A1: Budget to reach pilot results and investor outreach
A2: Estimates only. Blue = input. Replace with quotes. Salaries come from the Roles sheet; third-party costs come from the Roadmap sheet.
A4: Line | B4: AED | C4: Basis
A5: A. Third-party and government costs by phase
A6: P0 Validate | B6: =SUMIFS(Roadmap!$P$5:$P$59,Roadmap!$B$5:$B$59,"P0 Validate") -> 25500 | C6: Roadmap sheet
A7: P1 Set up | B7: =SUMIFS(Roadmap!$P$5:$P$59,Roadmap!$B$5:$B$59,"P1 Set up") -> 93000 | C7: Roadmap sheet: licence, office, cards, insurance
A8: P2 Pilot | B8: =SUMIFS(Roadmap!$P$5:$P$59,Roadmap!$B$5:$B$59,"P2 Pilot") -> 49000 | C8: Roadmap sheet: product, data, marketing
A9: P3 Raise | B9: =SUMIFS(Roadmap!$P$5:$P$59,Roadmap!$B$5:$B$59,"P3 Raise") -> 8000 | C9: Roadmap sheet: legal
A10: Subtotal A | B10: =SUM(B6:B9) -> 175500
A11: B. People costs (to week 13) | B11: =Roles!H17 -> 240000 | C11: Roles sheet
A12: C. Contingency rate | B12: 0.15 | C12: Assumption: 15% of A + B
A13: Contingency amount | B13: =B12*(B10+B11) -> 62325
A14: Operating cash needed (A + B + contingency) | B14: =B10+B11+B13 -> 477825
A15: D. Share capital to deposit (not an expense) | B15: 100000 | C15: Source: minimum capital for a standard RERA brokerage starts at AED 100,000 (Takween Advisory). Confirm with your PRO.
A16: Total cash to have available | B16: =B14+B15 -> 577825
A17: Funds already committed by founders (enter) | B17: 0 | C17: Enter your own number
A18: Funding gap | B18: =MAX(0,B16-B17) -> 577825 | C18: Amount to bridge before or through the raise
A19: Funding gap in USD (at 3.6725) | B19: =B18/3.6725 -> 157338.33 | C19: AED is pegged to USD at 3.6725

Sheet Deck Storyline
A1: Pitch deck storyline
A2: Problem-first. Each slide lists the evidence it needs and where that evidence comes from in this plan.
A4: Slide | B4: Title | C4: Key message | D4: Evidence needed and source | E4: Owner | F4: Draft by week | G4: Status
A5: 1 | B5: Cover and one-liner | C5: One sentence: what you do, for whom, and the outcome. | D5: Name, logo, one-liner, contact | E5: Founder | F5: 3 | G5: Not started
A6: 2 | B6: The problem | C6: Buying property in the UAE is slow, opaque and risky, especially for overseas buyers. Show 3 pains with numbers. | D6: Survey: H1 reliable information, H2 inaccurate listings, H3 hidden costs, H4 paperwork; 5 quotes | E6: Founder | F6: 5 | G6: Not started
A7: 3 | B7: Who feels it | C7: Name the first customer and show how many there are. | D7: Survey segments; DLD data: foreign buyers 85-88% of transactions; buyer origins | E7: Head of Growth | F7: 5 | G7: Not started
A8: 4 | B8: Why now | C8: Digital transfer is live (DLD Digital Sale, ADREC digital journey), record volumes, new broker rules. | D8: DLD and ADREC announcements; market volumes 2025 and H1 2026 | E8: Founder | F8: 4 | G8: Not started
A9: 5 | B9: The solution | C9: One app and one accountable company from research to keys. | D9: Journey map; one-page flow diagram | E9: Founder | F9: 4 | G9: Not started
A10: 6 | B10: The product | C10: Screens: insights, 3D view, document and payment tracker, design and furniture. | D10: Figma prototype (Roadmap 2.02); user test result (2.03) | E10: Co-founder & CTO | F10: 7 | G10: Not started
A11: 7 | B11: How we make money | C11: Developer commission 3-7%, resale 2% fee, mortgage referral, furniture and design, B2B data. Show unit economics for one deal. | D11: Earlier research brief; pilot actual commission (Roadmap 2.15) | E11: Fractional CFO | F11: 9 | G11: Not started
A12: 8 | B12: Market size | C12: Top-down and bottom-up. Fee pool vs total transaction value. | D12: Earlier research brief: TAM, SAM, SOM | E12: Fractional CFO | F12: 8 | G12: Not started
A13: 9 | B13: Traction and pilot results | C13: Waitlist, LOIs, pilot KPIs, quotes, case studies. | D13: Gates G0 and G2; Roadmap 2.16 | E13: Founder | F13: 12 | G13: Not started
A14: 10 | B14: Go-to-market and referral engine | C14: How customers arrive, why the referral network is compliant and scalable. | D14: Survey G section (willingness to refer); legal opinion (Roadmap 0.08); referral terms (2.08) | E14: Head of Growth | F14: 12 | G14: Not started
A15: 11 | B15: Competition and edge | C15: Honest map of portals, Huspy, PRYPCO, Oliva; what you do that they do not. | D15: Mystery-shop teardown (Roadmap 0.07) | E15: Founder | F15: 6 | G15: Not started
A16: 12 | B16: Regulation and risk | C16: Licensed brokerage, AML, escrow routing, data protection. Investors worry most about this slide. | D16: Licence pack (M1), goAML, payment flow (1.14), insurance | E16: Compliance & AML Officer | F16: 9 | G16: Not started
... A20: 16 | B20: Appendix | C20: Survey detail, interview themes, legal summary, product roadmap. | D20: Survey workbook; data room | E20: Founder | F20: 12 | G20: Not started

Sheet Sources
A1: Sources and assumptions
A2: Research current at October 2026. Fees and rules change; confirm with DLD, RERA and your setup consultant.
A4: Used for | B4: Source | C4: Link
A5: Broker licence steps, trade licence, RERA registration, office rule, fees | B5: Oliva: Dubai real estate brokerage regulations 2026 | C5: https://joinoliva.com/en/learn/blog/dubai-real-estate-brokerage-regulations-2026
A6: Broker card fees, DREI CTREB course, RERA registration, minimum capital AED 100,000 | B6: Takween Advisory: How to get a RERA licence in Dubai | C6: https://takweenadvisory.ae/en/blog/how-to-get-rera-license-dubai
A7: Cost ranges for opening a brokerage | B7: Shuraa: Cost of opening a real estate brokerage in Dubai | C7: https://www.shuraa.com/blog/2019/07/what-is-the-cost-of-opening-a-real-estate-brokerage-in-dubai.html
A8: Broker obligations and code of ethics | B8: Afridi & Angell: Responsibilities and Code of Ethics for Real Estate Brokers | C8: https://afridi-angell.com/wp-content/uploads/2026/01/inBrief-Responsibilities-and-Code-of-Ethics-for-Real-Estate-Brokers-in-Dubai.pdf
A9: AML duties for brokers, goAML, AED 55,000 cash reporting | B9: AML UAE: AML regulations for DNFBPs in UAE | C9: https://amluae.com/aml-regulations-for-dnfbps-in-uae/
A10: DLD Digital Sale service | B10: Dubai Land Department: Buy or sell property via DubaiNow | C10: https://dubailand.gov.ae/en/eservices/buy-or-sell-property-via-dubai-now/
A11: ADREC digital journey | B11: WAM: ADREC launches Digital Buy & Sell Journey | C11: https://www.wam.ae/en/article/bm6n7kr-adrec-launches-digital-buy-sell-journey
A12: Estimates marked "Estimate" in the Roadmap and Roles sheets | B12: Planning assumptions by the author; replace with quotes and real salaries | C12: -
